Traceback (most recent call last):
  File "/home/tx_h-yamashita/spp_20.02_doc/bin/../src/spp-ctl/spp-ctl", line 11, in <module>
    sys.exit(main())
  File "/home/tx_h-yamashita/spp_20.02_doc/src/spp-ctl/spp_ctl.py", line 269, in main
    args.api_port)
  File "/home/tx_h-yamashita/spp_20.02_doc/src/spp-ctl/spp_ctl.py", line 33, in __init__
    self.init_connection(pri_port, sec_port)
  File "/home/tx_h-yamashita/spp_20.02_doc/src/spp-ctl/spp_ctl.py", line 41, in init_connection
    self.pri_sock.bind((self.ip_addr, pri_port))
OSError: [Errno 98] Address already in use
